discarding /home/applications/miniconda2.7/bin from PATH
prepending /home/data/nbc/athena/athena/env/bin to PATH
Traceback (most recent call last):
  File "/scratch/jhays006/athena/test_run.py", line 6, in <module>
    data_preparation.generate_gazetteers()
  File "/home/data/nbc/athena/athena/data_preparation.py", line 58, in generate_gazetteers
    metadata_gazs = gazetteers.generate_metadata_gazetteers(pmids)
  File "/home/data/nbc/athena/athena/gazetteers.py", line 59, in generate_metadata_gazetteers
    h = Entrez.efetch(db="pubmed", id=pmid, rettype="medline", retmode="text")
  File "/home/data/nbc/athena/athena/env/lib/python2.7/site-packages/Bio/Entrez/__init__.py", line 155, in efetch
    return _open(cgi, variables, post)
  File "/home/data/nbc/athena/athena/env/lib/python2.7/site-packages/Bio/Entrez/__init__.py", line 516, in _open
    handle = _urlopen(cgi)
  File "/home/data/nbc/athena/athena/env/lib/python2.7/urllib2.py", line 154, in urlopen
    return opener.open(url, data, timeout)
  File "/home/data/nbc/athena/athena/env/lib/python2.7/urllib2.py", line 431, in open
    response = self._open(req, data)
  File "/home/data/nbc/athena/athena/env/lib/python2.7/urllib2.py", line 449, in _open
    '_open', req)
  File "/home/data/nbc/athena/athena/env/lib/python2.7/urllib2.py", line 409, in _call_chain
    result = func(*args)
  File "/home/data/nbc/athena/athena/env/lib/python2.7/urllib2.py", line 1227, in http_open
    return self.do_open(httplib.HTTPConnection, req)
  File "/home/data/nbc/athena/athena/env/lib/python2.7/urllib2.py", line 1197, in do_open
    raise URLError(err)
urllib2.URLError: <urlopen error [Errno 101] Network is unreachable>
